Workbook
Name AdvancedStats: ' #StatsTable'!$AO:$BB

Sheet 1 - Cover Page
B2: Nikola Jokic: Does Playing Defense Matter?
B3: A breakdown of how the 3x MVP performed in a team win in the 2024-25 Regular Season
B27: Analysis by Adrien Barnes
B28: 46009
B29: All data sourced from https://www.basketball-reference.com/players/j/jokicni01/gamelog/2025/

Sheet 2 - PointsScatter

Sheet 3 - Data Collection
B2: Differential (W - L) | D2: FG | E2: FGA | F2: FG% | G2: 3P | H2: 3PA | I2: 2P | J2: 2PA | K2: FT | L2: FTA | M2: FT%
B3: High | D3: -3 | E3: -4 | F3: 0.033 | G3: -1 | H3: 2 | I3: -3 | J3: -6 | K3: -7 | L3: -7 | M3: 0
B4: Low | D4: 2 | E4: 0 | F4: 0.131 | G4: 0 | H4: -1 | I4: 1 | J4: -1 | K4: 0 | L4: 0 | M4: 0.429
B5: Mean | D5: -1.2373188 | E5: -3.3188406 | F5: 0.042201087 | G5: -0.48731884 | H5: -1.8713768 | I5: -0.75 | J5: -1.4474638 | K5: 0.87318841 | L5: 0.73731884 | M5: 0.025609662
B8: Differential (W - L) | D8: ORB | E8: DRB | F8: TRB | G8: AST | H8: STL | I8: BLK | J8: TOV | K8: PF | L8: PTS
B9: High | D9: 1 | E9: 2 | F9: 2 | G9: 8 | H9: 2 | I9: 0 | J9: 0 | K9: 0 | L9: -13
B10: Low | D10: 0 | E10: 0 | F10: -1 | G10: 0 | H10: 0 | I10: 0 | J10: 1 | K10: 0 | L10: -2
B11: Mean | D11: -0.027173913 | E11: 1.0307971 | F11: 1.0036232 | G11: 1.4257246 | H11: 0.41485507 | I11: 0.2173913 | J11: -0.26268116 | K11: -0.072463768 | L11: -2.0887681
B13: Differential (W - L) | C13: +/- | D13: ORtg | E13: DRtg
B14: High | C14: 32 | D14: 26 | E14: -11
B15: Low | C15: 17 | D15: -7 | E15: -19
B16: Mean | C16: 20.394928 | D16: 14.027174 | E16: -12.958333

Sheet 4 - WinLoss Comparison

Sheet 5 - Regression

Sheet 6 - Conclusion

Sheet Abbrev. Approach
B2: Here is an abbreviated version of how I approached this project
B4: 1. Decided on baskteball topic to make it fun
B5: 2. Pulled 2 data sets from website provided and imported to Excel
B6: 3. Consolidated and cleaned the data for analysis
C7: Matching stats of the 2 tables to the correct games
C8: Used TEXTBEFORE and TEXTAFTER functions to breakdown game scores
C9: Formated minutes to be pulled if needed
C10: Made percentage entires uniform (XX.xx vs 0.xx)
C11: Inserted dashes for my blanks for easier navigation
B12: 4. Started initial calcualtions of category totals and basic statistical measures
B13: 5. Calculated the difference in performance in a win - loss to identify any large swings
B14: 6. Identified DRtg as an area to explore and analyzed with visualizations and further analysis
B15: 7. Brought the analysis together and added commentary on respective worksheets

Sheet     #StatsTable
B1: Gplayed | C1: Gcar | D1: Gseason | E1: Date | F1: Team | G1: Home/Away | H1: Opp | I1: Result | J1: DENPts | K1: OppPts | L1: W/L | M1: CumulW | N1: CumulL | O1: GS | P1: MP | Q1: FG | R1: FGA | S1: FG% | T1: 3P | U1: 3PA | V1: 3P% | W1: 2P | X1: 2PA | Y1: 2P% | Z1: eFG% | AA1: FT | AB1: FTA | AC1: FT% | AD1: ORB | AE1: DRB | AF1: TRB | AG1: AST | AH1: STL | AI1: BLK | AJ1: TOV | AK1: PF | AL1: PTS | AM1: GmSc | AN1: +/- | AO1: TS% | AP1: eFG%2 | AQ1: ORB% | AR1: DRB% | AS1: TRB% | AT1: AST% | AU1: STL% | AV1: BLK% | AW1: TOV% | AX1: USG% | AY1: ORtg | AZ1: DRtg | BA1: GmSc3 | BB1: BPM
B2: 1 | C2: 676 | D2: 1 | E2: 45589 | F2: DEN | H2: OKC | I2: L, 87-102 | J2: =(_xlfn.TEXTBEFORE(_xlfn.TEXTAFTER($I2,", ",,1),"-",,1,1,))*1 -> 87 | K2: =(_xlfn.TEXTBEFORE(_xlfn.TEXTAFTER($I2,"-",,1)," ",,1,1,))*1 -> 102 | L2: =LEFT(' #StatsTable'!$I2,1) -> L | M2: 0 | N2: 1 | O2: * | P2: 1.4666667 | Q2: 6 | R2: 13 | S2: 0.462 | T2: 1 | U2: 3 | V2: 0.333 | W2: 5 | X2: 10 | Y2: 0.5 | Z2: 0.5 | AA2: 3 | AB2: 4 | AC2: 0.75 | AD2: 4 | AE2: 8 | AF2: 12 | AG2: 13 | AH2: 2 | AI2: 1 | AJ2: 3 | AK2: 3 | AL2: 16 | AM2: 21.7 | AN2: -9 | AO2: 0.542 | AP2: 0.5 | AQ2: 0.103 | AR2: 0.206 | AS2: 0.154 | AT2: 0.661 | AU2: 0.027 | AV2: 0.021 | AW2: 0.169 | AX2: 0.202 | AY2: 117 | AZ2: 99 | BA2: 21.7 | BB2: 14.3
B3: 2 | C3: 677 | D3: 2 | E3: 45591 | F3: DEN | H3: LAC | I3: L, 104-109 | J3: =(_xlfn.TEXTBEFORE(_xlfn.TEXTAFTER($I3,", ",,1),"-",,1,1,))*1 -> 104 | K3: =(_xlfn.TEXTBEFORE(_xlfn.TEXTAFTER($I3,"-",,1)," ",,1,1,))*1 -> 109 | L3: =LEFT(' #StatsTable'!$I3,1) -> L | M3: =IF(' #StatsTable'!$L3="W", M2+1,M2) -> 0 | N3: =IF(' #StatsTable'!$L3="L",N2+1,N2) -> 2 | O3: * | P3: 1.5319444 | Q3: 14 | R3: 26 | S3: 0.538 | T3: 7 | U3: 12 | V3: 0.583 | W3: 7 | X3: 14 | Y3: 0.5 | Z3: 0.673 | AA3: 6 | AB3: 8 | AC3: 0.75 | AD3: 3 | AE3: 6 | AF3: 9 | AG3: 4 | AH3: 2 | AI3: 1 | AJ3: 5 | AK3: 2 | AL3: 41 | AM3: 31.2 | AN3: 7 | AO3: 0.694 | AP3: 0.673 | AQ3: 0.091 | AR3: 0.206 | AS3: 0.145 | AT3: 0.312 | AU3: 0.028 | AV3: 0.027 | AW3: 0.145 | AX3: 0.419 | AY3: 122 | AZ3: 114 | BA3: 31.2 | BB3: 18.9
B4: 3 | C4: 678 | D4: 3 | E4: 45593 | F4: DEN | G4: @ | H4: TOR | I4: W, 127-125 (OT) | J4: =(_xlfn.TEXTBEFORE(_xlfn.TEXTAFTER($I4,", ",,1),"-",,1,1,))*1 -> 127 | K4: =(_xlfn.TEXTBEFORE(_xlfn.TEXTAFTER($I4,"-",,1)," ",,1,1,))*1 -> 125 | L4: =LEFT(' #StatsTable'!$I4,1) -> W | M4: =IF(' #StatsTable'!$L4="W", M3+1,M3) -> 1 | N4: =IF(' #StatsTable'!$L4="L",N3+1,N3) -> 2 | O4: * | P4: 1.8201389 | Q4: 18 | R4: 27 | S4: 0.667 | T4: 3 | U4: 5 | V4: 0.6 | W4: 15 | X4: 22 | Y4: 0.682 | Z4: 0.722 | AA4: 1 | AB4: 2 | AC4: 0.5 | AD4: 3 | AE4: 7 | AF4: 10 | AG4: 4 | AH4: 1 | AI4: 2 | AJ4: 3 | AK4: 2 | AL4: 40 | AM4: 33.5 | AN4: 9 | AO4: 0.717 | AP4: 0.722 | AQ4: 0.071 | AR4: 0.154 | AS4: 0.114 | AT4: 0.193 | AU4: 0.011 | AV4: 0.033 | AW4: 0.097 | AX4: 0.299 | AY4: 132 | AZ4: 112 | BA4: 33.5 | BB4: 12.2
B5: 4 | C5: 679 | D5: 4 | E5: 45594 | F5: DEN | G5: @ | H5: BRK | I5: W, 144-139 (OT) | J5: =(_xlfn.TEXTBEFORE(_xlfn.TEXTAFTER($I5,", ",,1),"-",,1,1,))*1 -> 144 | K5: =(_xlfn.TEXTBEFORE(_xlfn.TEXTAFTER($I5,"-",,1)," ",,1,1,))*1 -> 139 | L5: =LEFT(' #StatsTable'!$I5,1) -> W | M5: =IF(' #StatsTable'!$L5="W", M4+1,M4) -> 2 | N5: =IF(' #StatsTable'!$L5="L",N4+1,N4) -> 2 | O5: * | P5: 1.6881944 | Q5: 9 | R5: 16 | S5: 0.563 | T5: 0 | U5: 0 | V5: - | W5: 9 | X5: 16 | Y5: 0.563 | Z5: 0.563 | AA5: 11 | AB5: 13 | AC5: 0.846 | AD5: 6 | AE5: 12 | AF5: 18 | AG5: 16 | AH5: 0 | AI5: 1 | AJ5: 1 | AK5: 3 | AL5: 29 | AM5: 38.1 | AN5: 8 | AO5: 0.668 | AP5: 0.563 | AQ5: 0.183 | AR5: 0.383 | AS5: 0.28 | AT5: 0.611 | AU5: 0 | AV5: 0.03 | AW5: 0.044 | AX5: 0.259 | AY5: 162 | AZ5: 129 | BA5: 38.1 | BB5: 17
B6: 5 | C6: 680 | D6: 5 | E6: 45597 | F6: DEN | G6: @ | H6: MIN | I6: L, 116-119 | J6: =(_xlfn.TEXTBEFORE(_xlfn.TEXTAFTER($I6,", ",,1),"-",,1,1,))*1 -> 116 | K6: =(_xlfn.TEXTBEFORE(_xlfn.TEXTAFTER($I6,"-",,1)," ",,1,1,))*1 -> 119 | L6: =LEFT(' #StatsTable'!$I6,1) -> L | M6: =IF(' #StatsTable'!$L6="W", M5+1,M5) -> 2 | N6: =IF(' #StatsTable'!$L6="L",N5+1,N5) -> 3 | O6: * | P6: 1.6541667 | Q6: 8 | R6: 16 | S6: 0.5 | T6: 2 | U6: 3 | V6: 0.667 | W6: 6 | X6: 13 | Y6: 0.462 | Z6: 0.563 | AA6: 8 | AB6: 10 | AC6: 0.8 | AD6: 2 | AE6: 7 | AF6: 9 | AG6: 13 | AH6: 3 | AI6: 1 | AJ6: 3 | AK6: 1 | AL6: 26 | AM6: 30.1 | AN6: 6 | AO6: 0.637 | AP6: 0.563 | AQ6: 0.051 | AR6: 0.229 | AS6: 0.13 | AT6: 0.502 | AU6: 0.037 | AV6: 0.029 | AW6: 0.128 | AX6: 0.236 | AY6: 138 | AZ6: 115 | BA6: 30.1 | BB6: 16.5
B7: 6 | C7: 681 | D7: 6 | E7: 45598 | F7: DEN | H7: UTA | I7: W, 129-103 | J7: =(_xlfn.TEXTBEFORE(_xlfn.TEXTAFTER($I7,", ",,1),"-",,1,1,))*1 -> 129 | K7: =(_xlfn.TEXTBEFORE(_xlfn.TEXTAFTER($I7,"-",,1)," ",,1,1,))*1 -> 103 | L7: =LEFT(' #StatsTable'!$I7,1) -> W | M7: =IF(' #StatsTable'!$L7="W", M6+1,M6) -> 3 | N7: =IF(' #StatsTable'!$L7="L",N6+1,N6) -> 3 | O7: * | P7: 1.2375 | Q7: 10 | R7: 18 | S7: 0.556 | T7: 3 | U7: 4 | V7: 0.75 | W7: 7 | X7: 14 | Y7: 0.5 | Z7: 0.639 | AA7: 4 | AB7: 4 | AC7: 1 | AD7: 5 | AE7: 11 | AF7: 16 | AG7: 9 | AH7: 1 | AI7: 0 | AJ7: 5 | AK7: 1 | AL7: 27 | AM7: 27.1 | AN7: 31 | AO7: 0.683 | AP7: 0.639 | AQ7: 0.162 | AR7: 0.434 | AS7: 0.284 | AT7: 0.457 | AU7: 0.015 | AV7: 0 | AW7: 0.202 | AX7: 0.315 | AY7: 131 | AZ7: 95 | BA7: 27.1 | BB7: 15.2
B8: 7 | C8: 682 | D8: 7 | E8: 45600 | F8: DEN | H8: TOR | I8: W, 121-119 | J8: =(_xlfn.TEXTBEFORE(_xlfn.TEXTAFTER($I8,", ",,1),"-",,1,1,))*1 -> 121 | K8: =(_xlfn.TEXTBEFORE(_xlfn.TEXTAFTER($I8,"-",,1)," ",,1,1,))*1 -> 119 | L8: =LEFT(' #StatsTable'!$I8,1) -> W | M8: =IF(' #StatsTable'!$L8="W", M7+1,M7) -> 4 | N8: =IF(' #StatsTable'!$L8="L",N7+1,N7) -> 3 | O8: * | P8: 1.5916667 | Q8: 10 | R8: 22 | S8: 0.455 | T8: 1 | U8: 5 | V8: 0.2 | W8: 9 | X8: 17 | Y8: 0.529 | Z8: 0.477 | AA8: 7 | AB8: 8 | AC8: 0.875 | AD8: 5 | AE8: 9 | AF8: 14 | AG8: 13 | AH8: 1 | AI8: 2 | AJ8: 7 | AK8: 2 | AL8: 28 | AM8: 26.1 | AN8: -1 | AO8: 0.549 | AP8: 0.477 | AQ8: 0.153 | AR8: 0.257 | AS8: 0.207 | AT8: 0.574 | AU8: 0.012 | AV8: 0.039 | AW8: 0.215 | AX8: 0.35 | AY8: 114 | AZ8: 113 | BA8: 26.1 | BB8: 5.4
B9: 8 | C9: 683 | D9: 8 | E9: 45602 | F9: DEN | H9: OKC | I9: W, 124-122 | J9: =(_xlfn.TEXTBEFORE(_xlfn.TEXTAFTER($I9,", ",,1),"-",,1,1,))*1 -> 124 | K9: =(_xlfn.TEXTBEFORE(_xlfn.TEXTAFTER($I9,"-",,1)," ",,1,1,))*1 -> 122 | L9: =LEFT(' #StatsTable'!$I9,1) -> W | M9: =IF(' #StatsTable'!$L9="W", M8+1,M8) -> 5 | N9: =IF(' #StatsTable'!$L9="L",N8+1,N8) -> 3 | O9: * | P9: 1.6451389 | Q9: 9 | R9: 20 | S9: 0.45 | T9: 1 | U9: 3 | V9: 0.333 | W9: 8 | X9: 17 | Y9: 0.471 | Z9: 0.475 | AA9: 4 | AB9: 6 | AC9: 0.667 | AD9: 7 | AE9: 13 | AF9: 20 | AG9: 16 | AH9: 2 | AI9: 2 | AJ9: 5 | AK9: 2 | AL9: 23 | AM9: 29.4 | AN9: 8 | AO9: 0.508 | AP9: 0.475 | AQ9: 0.181 | AR9: 0.287 | AS9: 0.238 | AT9: 0.626 | AU9: 0.023 | AV9: 0.041 | AW9: 0.181 | AX9: 0.277 | AY9: 121 | AZ9: 105 | BA9: 29.4 | BB9: 12.1
B10: 9 | C10: 684 | D10: 9 | E10: 45604 | F10: DEN | H10: MIA | I10: W, 135-122 | J10: =(_xlfn.TEXTBEFORE(_xlfn.TEXTAFTER($I10,", ",,1),"-",,1,1,))*1 -> 135 | K10: =(_xlfn.TEXTBEFORE(_xlfn.TEXTAFTER($I10,"-",,1)," ",,1,1,))*1 -> 122 | L10: =LEFT(' #StatsTable'!$I10,1) -> W | M10: =IF(' #StatsTable'!$L10="W", M9+1,M9) -> 6 | N10: =IF(' #StatsTable'!$L10="L",N9+1,N9) -> 3 | O10: * | P10: 1.6666667 | Q10: 11 | R10: 13 | S10: 0.846 | T10: 1 | U10: 1 | V10: 1 | W10: 10 | X10: 12 | Y10: 0.833 | Z10: 0.885 | AA10: 7 | AB10: 7 | AC10: 1 | AD10: 2 | AE10: 9 | AF10: 11 | AG10: 14 | AH10: 2 | AI10: 0 | AJ10: 5 | AK10: 2 | AL10: 30 | AM10: 35.4 | AN10: 26 | AO10: 0.933 | AP10: 0.885 | AQ10: 0.08 | AR10: 0.257 | AS10: 0.183 | AT10: 0.457 | AU10: 0.024 | AV10: 0 | AW10: 0.237 | AX10: 0.236 | AY10: 162 | AZ10: 117 | BA10: 35.4 | BB10: 14.1
B11: 10 | C11: 685 | D11: 10 | E11: 45606 | F11: DEN | H11: DAL | I11: W, 122-120 | J11: =(_xlfn.TEXTBEFORE(_xlfn.TEXTAFTER($I11,", ",,1),"-",,1,1,))*1 -> 122 | K11: =(_xlfn.TEXTBEFORE(_xlfn.TEXTAFTER($I11,"-",,1)," ",,1,1,))*1 -> 120 | L11: =LEFT(' #StatsTable'!$I11,1) -> W | M11: =IF(' #StatsTable'!$L11="W", M10+1,M10) -> 7 | N11: =IF(' #StatsTable'!$L11="L",N10+1,N10) -> 3 | O11: * | P11: 1.5840278 | Q11: 13 | R11: 21 | S11: 0.619 | T11: 3 | U11: 3 | V11: 1 | W11: 10 | X11: 18 | Y11: 0.556 | Z11: 0.69 | AA11: 8 | AB11: 8 | AC11: 1 | AD11: 8 | AE11: 10 | AF11: 18 | AG11: 15 | AH11: 3 | AI11: 0 | AJ11: 4 | AK11: 2 | AL11: 37 | AM11: 44.8 | AN11: 13 | AO11: 0.754 | AP11: 0.69 | AQ11: 0.224 | AR11: 0.301 | AS11: 0.261 | AT11: 0.663 | AU11: 0.039 | AV11: 0 | AW11: 0.14 | AX11: 0.326 | AY11: 154 | AZ11: 117 | BA11: 44.8 | BB11: 26.6
B12: 10 | D12: 11 | E12: 45611 | F12: DEN | G12: @ | H12: NOP | I12: L, 94-101 | J12: =(_xlfn.TEXTBEFORE(_xlfn.TEXTAFTER($I12,", ",,1),"-",,1,1,))*1 -> 94 | K12: =(_xlfn.TEXTBEFORE(_xlfn.TEXTAFTER($I12,"-",,1)," ",,1,1,))*1 -> 101 | L12: =LEFT(' #StatsTable'!$I12,1) -> L | M12: =IF(' #StatsTable'!$L12="W", M11+1,M11) -> 7 | N12: =IF(' #StatsTable'!$L12="L",N11+1,N11) -> 4 | O12: Inactive | P12: - | Q12: - | R12: - | S12: - | T12: - | U12: - | V12: - | W12: - | X12: - | Y12: - | Z12: - | AA12: - | AB12: - | AC12: - | AD12: - | AE12: - | AF12: - | AG12: - | AH12: - | AI12: - | AJ12: - | AK12: - | AL12: - | AM12: - | AN12: - | AO12: - | AP12: - | AQ12: - | AR12: - | AS12: - | AT12: - | AU12: - | AV12: - | AW12: - | AX12: - | AY12: - | AZ12: - | BA12: - | BB12: -
B13: 10 | D13: 12 | E13: 45613 | F13: DEN | G13: @ | H13: MEM | I13: L, 90-105 | J13: =(_xlfn.TEXTBEFORE(_xlfn.TEXTAFTER($I13,", ",,1),"-",,1,1,))*1 -> 90 | K13: =(_xlfn.TEXTBEFORE(_xlfn.TEXTAFTER($I13,"-",,1)," ",,1,1,))*1 -> 105 | L13: =LEFT(' #StatsTable'!$I13,1) -> L | M13: =IF(' #StatsTable'!$L13="W", M12+1,M12) -> 7 | N13: =IF(' #StatsTable'!$L13="L",N12+1,N12) -> 5 | O13: Inactive | P13: - | Q13: - | R13: - | S13: - | T13: - | U13: - | V13: - | W13: - | X13: - | Y13: - | Z13: - | AA13: - | AB13: - | AC13: - | AD13: - | AE13: - | AF13: - | AG13: - | AH13: - | AI13: - | AJ13: - | AK13: - | AL13: - | AM13: - | AN13: - | AO13: - | AP13: - | AQ13: - | AR13: - | AS13: - | AT13: - | AU13: - | AV13: - | AW13: - | AX13: - | AY13: - | AZ13: - | BA13: - | BB13: -
B14: 10 | D14: 13 | E14: 45615 | F14: DEN | G14: @ | H14: MEM | I14: W, 122-110 | J14: =(_xlfn.TEXTBEFORE(_xlfn.TEXTAFTER($I14,", ",,1),"-",,1,1,))*1 -> 122 | K14: =(_xlfn.TEXTBEFORE(_xlfn.TEXTAFTER($I14,"-",,1)," ",,1,1,))*1 -> 110 | L14: =LEFT(' #StatsTable'!$I14,1) -> W | M14: =IF(' #StatsTable'!$L14="W", M13+1,M13) -> 8 | N14: =IF(' #StatsTable'!$L14="L",N13+1,N13) -> 5 | O14: Inactive | P14: - | Q14: - | R14: - | S14: - | T14: - | U14: - | V14: - | W14: - | X14: - | Y14: - | Z14: - | AA14: - | AB14: - | AC14: - | AD14: - | AE14: - | AF14: - | AG14: - | AH14: - | AI14: - | AJ14: - | AK14: - | AL14: - | AM14: - | AN14: - | AO14: - | AP14: - | AQ14: - | AR14: - | AS14: - | AT14: - | AU14: - | AV14: - | AW14: - | AX14: - | AY14: - | AZ14: - | BA14: - | BB14: -
B15: 11 | C15: 686 | D15: 14 | E15: 45618 | F15: DEN | H15: DAL | I15: L, 120-123 | J15: =(_xlfn.TEXTBEFORE(_xlfn.TEXTAFTER($I15,", ",,1),"-",,1,1,))*1 -> 120 | K15: =(_xlfn.TEXTBEFORE(_xlfn.TEXTAFTER($I15,"-",,1)," ",,1,1,))*1 -> 123 | L15: =LEFT(' #StatsTable'!$I15,1) -> L | M15: =IF(' #StatsTable'!$L15="W", M14+1,M14) -> 8 | N15: =IF(' #StatsTable'!$L15="L",N14+1,N14) -> 6 | O15: * | P15: 1.6444444 | Q15: 13 | R15: 22 | S15: 0.591 | T15: 2 | U15: 2 | V15: 1 | W15: 11 | X15: 20 | Y15: 0.55 | Z15: 0.636 | AA15: 5 | AB15: 7 | AC15: 0.714 | AD15: 6 | AE15: 11 | AF15: 17 | AG15: 10 | AH15: 0 | AI15: 0 | AJ15: 3 | AK15: 0 | AL15: 33 | AM15: 33.5 | AN15: 4 | AO15: 0.658 | AP15: 0.636 | AQ15: 0.155 | AR15: 0.343 | AS15: 0.24 | AT15: 0.447 | AU15: 0 | AV15: 0 | AW15: 0.107 | AX15: 0.29 | AY15: 139 | AZ15: 121 | BA15: 33.5 | BB15: 12.2
B16: 12 | C16: 687 | D16: 15 | E16: 45619 | F16: DEN | G16: @ | H16: LAL | I16: W, 127-102 | J16: =(_xlfn.TEXTBEFORE(_xlfn.TEXTAFTER($I16,", ",,1),"-",,1,1,))*1 -> 127 | K16: =(_xlfn.TEXTBEFORE(_xlfn.TEXTAFTER($I16,"-",,1)," ",,1,1,))*1 -> 102 | L16: =LEFT(' #StatsTable'!$I16,1) -> W | M16: =IF(' #StatsTable'!$L16="W", M15+1,M15) -> 9 | N16: =IF(' #StatsTable'!$L16="L",N15+1,N15) -> 6 | O16: * | P16: 1.5256944 | Q16: 12 | R16: 20 | S16: 0.6 | T16: 3 | U16: 7 | V16: 0.429 | W16: 9 | X16: 13 | Y16: 0.692 | Z16: 0.675 | AA16: 7 | AB16: 8 | AC16: 0.875 | AD16: 2 | AE16: 11 | AF16: 13 | AG16: 8 | AH16: 2 | AI16: 1 | AJ16: 6 | AK16: 3 | AL16: 34 | AM16: 30.2 | AN16: 39 | AO16: 0.723 | AP16: 0.675 | AQ16: 0.077 | AR16: 0.313 | AS16: 0.213 | AT16: 0.306 | AU16: 0.026 | AV16: 0.025 | AW16: 0.203 | AX16: 0.357 | AY16: 126 | AZ16: 95 | BA16: 30.2 | BB16: 9.9
B17: 13 | C17: 688 | D17: 16 | E17: 45621 | F17: DEN | H17: NYK | I17: L, 118-145 | J17: =(_xlfn.TEXTBEFORE(_xlfn.TEXTAFTER($I17,", ",,1),"-",,1,1,))*1 -> 118 | K17: =(_xlfn.TEXTBEFORE(_xlfn.TEXTAFTER($I17,"-",,1)," ",,1,1,))*1 -> 145 | L17: =LEFT(' #StatsTable'!$I17,1) -> L | M17: =IF(' #StatsTable'!$L17="W", M16+1,M16) -> 9 | N17: =IF(' #StatsTable'!$L17="L",N16+1,N16) -> 7 | O17: * | P17: 1.3263889 | Q17: 9 | R17: 20 | S17: 0.45 | T17: 2 | U17: 7 | V17: 0.286 | W17: 7 | X17: 13 | Y17: 0.538 | Z17: 0.5 | AA17: 2 | AB17: 2 | AC17: 1 | AD17: 3 | AE17: 4 | AF17: 7 | AG17: 7 | AH17: 1 | AI17: 0 | AJ17: 0 | AK17: 1 | AL17: 22 | AM17: 20.4 | AN17: -20 | AO17: 0.527 | AP17: 0.5 | AQ17: 0.101 | AR17: 0.195 | AS17: 0.139 | AT17: 0.385 | AU17: 0.015 | AV17: 0 | AW17: 0 | AX17: 0.274 | AY17: 127 | AZ17: 144 | BA17: 20.4 | BB17: 7.2
B18: 14 | C18: 689 | D18: 17 | E18: 45623 | F18: DEN | G18: @ | H18: UTA | I18: W, 122-103 | J18: =(_xlfn.TEXTBEFORE(_xlfn.TEXTAFTER($I18,", ",,1),"-",,1,1,))*1 -> 122 | K18: =(_xlfn.TEXTBEFORE(_xlfn.TEXTAFTER($I18,"-",,1)," ",,1,1,))*1 -> 103 | L18: =LEFT(' #StatsTable'!$I18,1) -> W | M18: =IF(' #StatsTable'!$L18="W", M17+1,M17) -> 10 | N18: =IF(' #StatsTable'!$L18="L",N17+1,N17) -> 7 | O18: * | P18: 1.4006944 | Q18: 13 | R18: 19 | S18: 0.684 | T18: 2 | U18: 3 | V18: 0.667 | W18: 11 | X18: 16 | Y18: 0.688 | Z18: 0.737 | AA18: 2 | AB18: 3 | AC18: 0.667 | AD18: 3 | AE18: 7 | AF18: 10 | AG18: 7 | AH18: 1 | AI18: 1 | AJ18: 1 | AK18: 1 | AL18: 30 | AM18: 30.9 | AN18: 20 | AO18: 0.738 | AP18: 0.737 | AQ18: 0.119 | AR18: 0.2 | AS18: 0.166 | AT18: 0.364 | AU18: 0.015 | AV18: 0.03 | AW18: 0.047 | AX18: 0.29 | AY18: 154 | AZ18: 107 | BA18: 30.9 | BB18: 15.3
B19: 15 | C19: 690 | D19: 18 | E19: 45627 | F19: DEN | G19: @ | H19: LAC | I19: L, 122-126 | J19: =(_xlfn.TEXTBEFORE(_xlfn.TEXTAFTER($I19,", ",,1),"-",,1,1,))*1 -> 122 | K19: =(_xlfn.TEXTBEFORE(_xlfn.TEXTAFTER($I19,"-",,1)," ",,1,1,))*1 -> 126 | L19: =LEFT(' #StatsTable'!$I19,1) -> L | M19: =IF(' #StatsTable'!$L19="W", M18+1,M18) -> 10 | N19: =IF(' #StatsTable'!$L19="L",N18+1,N18) -> 8 | O19: * | P19: 1.6277778 | Q19: 12 | R19: 24 | S19: 0.5 | T19: 2 | U19: 7 | V19: 0.286 | W19: 10 | X19: 17 | Y19: 0.588 | Z19: 0.542 | AA19: 2 | AB19: 4 | AC19: 0.5 | AD19: 3 | AE19: 11 | AF19: 14 | AG19: 11 | AH19: 1 | AI19: 1 | AJ19: 5 | AK19: 3 | AL19: 28 | AM19: 23.8 | AN19: -7 | AO19: 0.543 | AP19: 0.542 | AQ19: 0.1 | AR19: 0.307 | AS19: 0.212 | AT19: 0.373 | AU19: 0.012 | AV19: 0.024 | AW19: 0.163 | AX19: 0.342 | AY19: 109 | AZ19: 120 | BA19: 23.8 | BB19: 3.7
B20: 16 | C20: 691 | D20: 19 | E20: 45629 | F20: DEN | H20: GSW | I20: W, 119-115 | J20: =(_xlfn.TEXTBEFORE(_xlfn.TEXTAFTER($I20,", ",,1),"-",,1,1,))*1 -> 119 | K20: =(_xlfn.TEXTBEFORE(_xlfn.TEXTAFTER($I20,"-",,1)," ",,1,1,))*1 -> 115 | L20: =LEFT(' #StatsTable'!$I20,1) -> W | M20: =IF(' #StatsTable'!$L20="W", M19+1,M19) -> 11 | N20: =IF(' #StatsTable'!$L20="L",N19+1,N19) -> 8 | O20: * | P20: 1.6680556 | Q20: 14 | R20: 24 | S20: 0.583 | T20: 3 | U20: 4 | V20: 0.75 | W20: 11 | X20: 20 | Y20: 0.55 | Z20: 0.646 | AA20: 7 | AB20: 9 | AC20: 0.778 | AD20: 2 | AE20: 8 | AF20: 10 | AG20: 6 | AH20: 5 | AI20: 1 | AJ20: 4 | AK20: 1 | AL20: 38 | AM20: 35.3 | AN20: 23 | AO20: 0.68 | AP20: 0.646 | AQ20: 0.058 | AR20: 0.213 | AS20: 0.139 | AT20: 0.31 | AU20: 0.057 | AV20: 0.021 | AW20: 0.125 | AX20: 0.35 | AY20: 120 | AZ20: 100 | BA20: 35.3 | BB20: 14.2
B21: 17 | C21: 692 | D21: 20 | E21: 45631 | F21: DEN | G21: @ | H21: CLE | I21: L, 114-126 | J21: =(_xlfn.TEXTBEFORE(_xlfn.TEXTAFTER($I21,", ",,1),"-",,1,1,))*1 -> 114 | K21: =(_xlfn.TEXTBEFORE(_xlfn.TEXTAFTER($I21,"-",,1)," ",,1,1,))*1 -> 126 | L21: =LEFT(' #StatsTable'!$I21,1) -> L | M21: =IF(' #StatsTable'!$L21="W", M20+1,M20) -> 11 | N21: =IF(' #StatsTable'!$L21="L",N20+1,N20) -> 9 | O21: * | P21: 1.6111111 | Q21: 13 | R21: 26 | S21: 0.5 | T21: 0 | U21: 3 | V21: 0 | W21: 13 | X21: 23 | Y21: 0.565 | Z21: 0.5 | AA21: 1 | AB21: 1 | AC21: 1 | AD21: 3 | AE21: 17 | AF21: 20 | AG21: 11 | AH21: 3 | AI21: 0 | AJ21: 3 | AK21: 3 | AL21: 27 | AM21: 27.7 | AN21: -8 | AO21: 0.511 | AP21: 0.5 | AQ21: 0.079 | AR21: 0.431 | AS21: 0.259 | AT21: 0.457 | AU21: 0.034 | AV21: 0 | AW21: 0.102 | AX21: 0.3 | AY21: 109 | AZ21: 108 | BA21: 27.7 | BB21: 10.3
B22: 18 | C22: 693 | D22: 21 | E22: 45633 | F22: DEN | G22: @ | H22: WAS | I22: L, 113-122 | J22: =(_xlfn.TEXTBEFORE(_xlfn.TEXTAFTER($I22,", ",,1),"-",,1,1,))*1 -> 113 | K22: =(_xlfn.TEXTBEFORE(_xlfn.TEXTAFTER($I22,"-",,1)," ",,1,1,))*1 -> 122 | L22: =LEFT(' #StatsTable'!$I22,1) -> L | M22: =IF(' #StatsTable'!$L22="W", M21+1,M21) -> 11 | N22: =IF(' #StatsTable'!$L22="L",N21+1,N21) -> 10 | O22: * | P22: 1.6104167 | Q22: 22 | R22: 39 | S22: 0.564 | T22: 3 | U22: 6 | V22: 0.5 | W22: 19 | X22: 33 | Y22: 0.576 | Z22: 0.603 | AA22: 9 | AB22: 13 | AC22: 0.692 | AD22: 7 | AE22: 9 | AF22: 16 | AG22: 8 | AH22: 1 | AI22: 0 | AJ22: 5 | AK22: 5 | AL22: 56 | AM22: 43.1 | AN22: -1 | AO22: 0.626 | AP22: 0.603 | AQ22: 0.185 | AR22: 0.238 | AS22: 0.211 | AT22: 0.532 | AU22: 0.012 | AV22: 0 | AW22: 0.101 | AX22: 0.507 | AY22: 124 | AZ22: 118 | BA22: 43.1 | BB22: 16.9
B23: 19 | C23: 694 | D23: 22 | E23: 45634 | F23: DEN | G23: @ | H23: ATL | I23: W, 141-111 | J23: =(_xlfn.TEXTBEFORE(_xlfn.TEXTAFTER($I23,", ",,1),"-",,1,1,))*1 -> 141 | K23: =(_xlfn.TEXTBEFORE(_xlfn.TEXTAFTER($I23,"-",,1)," ",,1,1,))*1 -> 111 | L23: =LEFT(' #StatsTable'!$I23,1) -> W | M23: =IF(' #StatsTable'!$L23="W", M22+1,M22) -> 12 | N23: =IF(' #StatsTable'!$L23="L",N22+1,N22) -> 10 | O23: * | P23: 1.4604167 | Q23: 17 | R23: 29 | S23: 0.586 | T23: 3 | U23: 6 | V23: 0.5 | W23: 14 | X23: 23 | Y23: 0.609 | Z23: 0.638 | AA23: 11 | AB23: 13 | AC23: 0.846 | AD23: 3 | AE23: 11 | AF23: 14 | AG23: 8 | AH23: 3 | AI23: 0 | AJ23: 3 | AK23: 2 | AL23: 48 | AM23: 43.9 | AN23: 25 | AO23: 0.691 | AP23: 0.638 | AQ23: 0.124 | AR23: 0.274 | AS23: 0.218 | AT23: 0.335 | AU23: 0.039 | AV23: 0 | AW23: 0.08 | AX23: 0.432 | AY23: 137 | AZ23: 94 | BA23: 43.9 | BB23: 15.7
B24: 20 | C24: 695 | D24: 23 | E24: 45639 | F24: DEN | H24: LAC | I24: W, 120-98 | J24: =(_xlfn.TEXTBEFORE(_xlfn.TEXTAFTER($I24,", ",,1),"-",,1,1,))*1 -> 120 | K24: =(_xlfn.TEXTBEFORE(_xlfn.TEXTAFTER($I24,"-",,1)," ",,1,1,))*1 -> 98 | L24: =LEFT(' #StatsTable'!$I24,1) -> W | M24: =IF(' #StatsTable'!$L24="W", M23+1,M23) -> 13 | N24: =IF(' #StatsTable'!$L24="L",N23+1,N23) -> 10 | O24: * | P24: 1.2479167 | Q24: 6 | R24: 9 | S24: 0.667 | T24: 2 | U24: 2 | V24: 1 | W24: 4 | X24: 7 | Y24: 0.571 | Z24: 0.778 | AA24: 2 | AB24: 4 | AC24: 0.5 | AD24: 0 | AE24: 7 | AF24: 7 | AG24: 2 | AH24: 2 | AI24: 0 | AJ24: 5 | AK24: 2 | AL24: 16 | AM24: 11 | AN24: 14 | AO24: 0.743 | AP24: 0.778 | AQ24: 0 | AR24: 0.244 | AS24: 0.146 | AT24: 0.099 | AU24: 0.031 | AV24: 0 | AW24: 0.317 | AX24: 0.223 | AY24: 97 | AZ24: 93 | BA24: 11 | BB24: 0.4
B25: 21 | C25: 696 | D25: 24 | E25: 45642 | F25: DEN | G25: @ | H25: SAC | I25: W, 130-129 | J25: =(_xlfn.TEXTBEFORE(_xlfn.TEXTAFTER($I25,", ",,1),"-",,1,1,))*1 -> 130 | K25: =(_xlfn.TEXTBEFORE(_xlfn.TEXTAFTER($I25,"-",,1)," ",,1,1,))*1 -> 129 | L25: =LEFT(' #StatsTable'!$I25,1) -> W | M25: =IF(' #StatsTable'!$L25="W", M24+1,M24) -> 14 | N25: =IF(' #StatsTable'!$L25="L",N24+1,N24) -> 10 | O25: * | P25: 1.5958333 | Q25: 8 | R25: 19 | S25: 0.421 | T25: 1 | U25: 6 | V25: 0.167 | W25: 7 | X25: 13 | Y25: 0.538 | Z25: 0.447 | AA25: 3 | AB25: 4 | AC25: 0.75 | AD25: 2 | AE25: 12 | AF25: 14 | AG25: 13 | AH25: 2 | AI25: 1 | AJ25: 5 | AK25: 0 | AL25: 20 | AM25: 21.3 | AN25: 4 | AO25: 0.482 | AP25: 0.447 | AQ25: 0.054 | AR25: 0.295 | AS25: 0.181 | AT25: 0.398 | AU25: 0.023 | AV25: 0.019 | AW25: 0.194 | AX25: 0.253 | AY25: 105 | AZ25: 113 | BA25: 21.3 | BB25: 4.5
B26: 22 | C26: 697 | D26: 25 | E26: 45645 | F26: DEN | G26: @ | H26: POR | I26: L, 124-126 | J26: =(_xlfn.TEXTBEFORE(_xlfn.TEXTAFTER($I26,", ",,1),"-",,1,1,))*1 -> 124 | K26: =(_xlfn.TEXTBEFORE(_xlfn.TEXTAFTER($I26,"-",,1)," ",,1,1,))*1 -> 126 | L26: =LEFT(' #StatsTable'!$I26,1) -> L | M26: =IF(' #StatsTable'!$L26="W", M25+1,M25) -> 14 | N26: =IF(' #StatsTable'!$L26="L",N25+1,N25) -> 11 | O26: * | P26: 1.5256944 | Q26: 13 | R26: 18 | S26: 0.722 | T26: 4 | U26: 6 | V26: 0.667 | W26: 9 | X26: 12 | Y26: 0.75 | Z26: 0.833 | AA26: 4 | AB26: 4 | AC26: 1 | AD26: 0 | AE26: 6 | AF26: 6 | AG26: 8 | AH26: 1 | AI26: 0 | AJ26: 3 | AK26: 4 | AL26: 34 | AM26: 30.4 | AN26: -5 | AO26: 0.86 | AP26: 0.833 | AQ26: 0 | AR26: 0.167 | AS26: 0.093 | AT26: 0.35 | AU26: 0.013 | AV26: 0 | AW26: 0.132 | AX26: 0.278 | AY26: 150 | AZ26: 128 | BA26: 30.4 | BB26: 12.8
B27: 23 | C27: 698 | D27: 26 | E27: 45648 | F27: DEN | G27: @ | H27: NOP | I27: W, 132-129 (OT) | J27: =(_xlfn.TEXTBEFORE(_xlfn.TEXTAFTER($I27,", ",,1),"-",,1,1,))*1 -> 132 | K27: =(_xlfn.TEXTBEFORE(_xlfn.TEXTAFTER($I27,"-",,1)," ",,1,1,))*1 -> 129 | L27: =LEFT(' #StatsTable'!$I27,1) -> W | M27: =IF(' #StatsTable'!$L27="W", M26+1,M26) -> 15 | N27: =IF(' #StatsTable'!$L27="L",N26+1,N26) -> 11 | O27: * | P27: 1.7736111 | Q27: 11 | R27: 20 | S27: 0.55 | T27: 2 | U27: 3 | V27: 0.667 | W27: 9 | X27: 17 | Y27: 0.529 | Z27: 0.6 | AA27: 3 | AB27: 5 | AC27: 0.6 | AD27: 2 | AE27: 11 | AF27: 13 | AG27: 10 | AH27: 1 | AI27: 1 | AJ27: 3 | AK27: 5 | AL27: 27 | AM27: 25 | AN27: 6 | AO27: 0.608 | AP27: 0.6 | AQ27: 0.052 | AR27: 0.28 | AS27: 0.167 | AT27: 0.353 | AU27: 0.01 | AV27: 0.018 | AW27: 0.119 | AX27: 0.236 | AY27: 124 | AZ27: 108 | BA27: 25 | BB27: 4.9
B28: 24 | C28: 699 | D28: 27 | E28: 45649 | F28: DEN | H28: PHO | I28: W, 117-90 | J28: =(_xlfn.TEXTBEFORE(_xlfn.TEXTAFTER($I28,", ",,1),"-",,1,1,))*1 -> 117 | K28: =(_xlfn.TEXTBEFORE(_xlfn.TEXTAFTER($I28,"-",,1)," ",,1,1,))*1 -> 90 | L28: =LEFT(' #StatsTable'!$I28,1) -> W | M28: =IF(' #StatsTable'!$L28="W", M27+1,M27) -> 16 | N28: =IF(' #StatsTable'!$L28="L",N27+1,N27) -> 11 | O28: * | P28: 1.2395833 | Q28: 12 | R28: 17 | S28: 0.706 | T28: 4 | U28: 6 | V28: 0.667 | W28: 8 | X28: 11 | Y28: 0.727 | Z28: 0.824 | AA28: 4 | AB28: 5 | AC28: 0.8 | AD28: 0 | AE28: 2 | AF28: 2 | AG28: 7 | AH28: 0 | AI28: 0 | AJ28: 1 | AK28: 1 | AL28: 32 | AM28: 28.6 | AN28: 19 | AO28: 0.833 | AP28: 0.824 | AQ28: 0 | AR28: 0.073 | AS28: 0.038 | AT28: 0.424 | AU28: 0 | AV28: 0 | AW28: 0.05 | AX28: 0.305 | AY28: 162 | AZ28: 104 | BA28: 28.6 | BB28: 21.6
B29: 25 | C29: 700 | D29: 28 | E29: 45651 | F29: DEN | G29: @ | H29: PHO | I29: L, 100-110 | J29: =(_xlfn.TEXTBEFORE(_xlfn.TEXTAFTER($I29,", ",,1),"-",,1,1,))*1 -> 100 | K29: =(_xlfn.TEXTBEFORE(_xlfn.TEXTAFTER($I29,"-",,1)," ",,1,1,))*1 -> 110 | L29: =LEFT(' #StatsTable'!$I29,1) -> L | M29: =IF(' #StatsTable'!$L29="W", M28+1,M28) -> 16 | N29: =IF(' #StatsTable'!$L29="L",N28+1,N28) -> 12 | O29: * | P29: 1.575 | Q29: 10 | R29: 19 | S29: 0.526 | T29: 2 | U29: 7 | V29: 0.286 | W29: 8 | X29: 12 | Y29: 0.667 | Z29: 0.579 | AA29: 3 | AB29: 4 | AC29: 0.75 | AD29: 5 | AE29: 10 | AF29: 15 | AG29: 2 | AH29: 2 | AI29: 0 | AJ29: 2 | AK29: 1 | AL29: 25 | AM29: 22.8 | AN29: -3 | AO29: 0.602 | AP29: 0.579 | AQ29: 0.144 | AR29: 0.289 | AS29: 0.216 | AT29: 0.109 | AU29: 0.028 | AV29: 0 | AW29: 0.088 | AX29: 0.272 | AY29: 124 | AZ29: 112 | BA29: 22.8 | BB29: 8.9
B30: 26 | C30: 701 | D30: 29 | E30: 45653 | F30: DEN | H30: CLE | I30: L, 135-149 | J30: =(_xlfn.TEXTBEFORE(_xlfn.TEXTAFTER($I30,", ",,1),"-",,1,1,))*1 -> 135 | K30: =(_xlfn.TEXTBEFORE(_xlfn.TEXTAFTER($I30,"-",,1)," ",,1,1,))*1 -> 149 | L30: =LEFT(' #StatsTable'!$I30,1) -> L | M30: =IF(' #StatsTable'!$L30="W", M29+1,M29) -> 16 | N30: =IF(' #StatsTable'!$L30="L",N29+1,N29) -> 13 | O30: * | P30: 1.4895833 | Q30: 12 | R30: 19 | S30: 0.632 | T30: 0 | U30: 3 | V30: 0 | W30: 12 | X30: 16 | Y30: 0.75 | Z30: 0.632 | AA30: 3 | AB30: 4 | AC30: 0.75 | AD30: 3 | AE30: 11 | AF30: 14 | AG30: 13 | AH30: 3 | AI30: 0 | AJ30: 1 | AK30: 1 | AL30: 27 | AM30: 34.2 | AN30: -15 | AO30: 0.65 | AP30: 0.632 | AQ30: 0.109 | AR30: 0.379 | AS30: 0.247 | AT30: 0.473 | AU30: 0.038 | AV30: 0 | AW30: 0.046 | AX30: 0.254 | AY30: 150 | AZ30: 134 | BA30: 34.2 | BB30: 14.7
B31: 27 | C31: 702 | D31: 30 | E31: 45654 | F31: DEN | H31: DET | I31: W, 134-121 | J31: =(_xlfn.TEXTBEFORE(_xlfn.TEXTAFTER($I31,", ",,1),"-",,1,1,))*1 -> 134 | K31: =(_xlfn.TEXTBEFORE(_xlfn.TEXTAFTER($I31,"-",,1)," ",,1,1,))*1 -> 121 | L31: =LEFT(' #StatsTable'!$I31,1) -> W | M31: =IF(' #StatsTable'!$L31="W", M30+1,M30) -> 17 | N31: =IF(' #StatsTable'!$L31="L",N30+1,N30) -> 13 | O31: * | P31: 1.5513889 | Q31: 11 | R31: 17 | S31: 0.647 | T31: 4 | U31: 5 | V31: 0.8 | W31: 7 | X31: 12 | Y31: 0.583 | Z31: 0.765 | AA31: 11 | AB31: 14 | AC31: 0.786 | AD31: 1 | AE31: 8 | AF31: 9 | AG31: 8 | AH31: 0 | AI31: 0 | AJ31: 2 | AK31: 4 | AL31: 37 | AM31: 33.4 | AN31: 25 | AO31: 0.799 | AP31: 0.765 | AQ31: 0.038 | AR31: 0.219 | AS31: 0.143 | AT31: 0.324 | AU31: 0 | AV31: 0 | AW31: 0.079 | AX31: 0.29 | AY31: 158 | AZ31: 123 | BA31: 33.4 | BB31: 12.1
B32: 28 | C32: 703 | D32: 31 | E32: 45656 | F32: DEN | G32: @ | H32: UTA | I32: W, 132-121 | J32: =(_xlfn.TEXTBEFORE(_xlfn.TEXTAFTER($I32,", ",,1),"-",,1,1,))*1 -> 132 | K32: =(_xlfn.TEXTBEFORE(_xlfn.TEXTAFTER($I32,"-",,1)," ",,1,1,))*1 -> 121 | L32: =LEFT(' #StatsTable'!$I32,1) -> W | M32: =IF(' #StatsTable'!$L32="W", M31+1,M31) -> 18 | N32: =IF(' #StatsTable'!$L32="L",N31+1,N31) -> 13 | O32: * | P32: 1.5958333 | Q32: 14 | R32: 33 | S32: 0.424 | T32: 3 | U32: 9 | V32: 0.333 | W32: 11 | X32: 24 | Y32: 0.458 | Z32: 0.47 | AA32: 5 | AB32: 6 | AC32: 0.833 | AD32: 7 | AE32: 15 | AF32: 22 | AG32: 11 | AH32: 4 | AI32: 0 | AJ32: 2 | AK32: 0 | AL32: 36 | AM32: 37.2 | AN32: 20 | AO32: 0.505 | AP32: 0.47 | AQ32: 0.187 | AR32: 0.459 | AS32: 0.313 | AT32: 0.389 | AU32: 0.049 | AV32: 0 | AW32: 0.053 | AX32: 0.392 | AY32: 125 | AZ32: 110 | BA32: 37.2 | BB32: 13.6
B33: 29 | C33: 704 | D33: 32 | E33: 45658 | F33: DEN | H33: ATL | I33: W, 139-120 | J33: =(_xlfn.TEXTBEFORE(_xlfn.TEXTAFTER($I33,", ",,1),"-",,1,1,))*1 -> 139 | K33: =(_xlfn.TEXTBEFORE(_xlfn.TEXTAFTER($I33,"-",,1)," ",,1,1,))*1 -> 120 | L33: =LEFT(' #StatsTable'!$I33,1) -> W | M33: =IF(' #StatsTable'!$L33="W", M32+1,M32) -> 19 | N33: =IF(' #StatsTable'!$L33="L",N32+1,N32) -> 13 | O33: * | P33: 1.2298611 | Q33: 8 | R33: 16 | S33: 0.5 | T33: 1 | U33: 1 | V33: 1 | W33: 7 | X33: 15 | Y33: 0.467 | Z33: 0.531 | AA33: 6 | AB33: 6 | AC33: 1 | AD33: 3 | AE33: 14 | AF33: 17 | AG33: 15 | AH33: 0 | AI33: 1 | AJ33: 2 | AK33: 2 | AL33: 23 | AM33: 29.7 | AN33: 31 | AO33: 0.617 | AP33: 0.531 | AQ33: 0.136 | AR33: 0.446 | AS33: 0.318 | AT33: 0.61 | AU33: 0 | AV33: 0.03 | AW33: 0.097 | AX33: 0.289 | AY33: 139 | AZ33: 104 | BA33: 29.7 | BB33: 15.1
B34: 30 | C34: 705 | D34: 33 | E34: 45660 | F34: DEN | H34: SAS | I34: L, 110-113 | J34: =(_xlfn.TEXTBEFORE(_xlfn.TEXTAFTER($I34,", ",,1),"-",,1,1,))*1 -> 110 | K34: =(_xlfn.TEXTBEFORE(_xlfn.TEXTAFTER($I34,"-",,1)," ",,1,1,))*1 -> 113 | L34: =LEFT(' #StatsTable'!$I34,1) -> L | M34: =IF(' #StatsTable'!$L34="W", M33+1,M33) -> 19 | N34: =IF(' #StatsTable'!$L34="L",N33+1,N33) -> 14 | O34: * | P34: 1.5270833 | Q34: 15 | R34: 36 | S34: 0.417 | T34: 3 | U34: 10 | V34: 0.3 | W34: 12 | X34: 26 | Y34: 0.462 | Z34: 0.458 | AA34: 8 | AB34: 9 | AC34: 0.889 | AD34: 4 | AE34: 14 | AF34: 18 | AG34: 9 | AH34: 2 | AI34: 0 | AJ34: 2 | AK34: 3 | AL34: 41 | AM34: 33.5 | AN34: 7 | AO34: 0.513 | AP34: 0.458 | AQ34: 0.101 | AR34: 0.367 | AS34: 0.231 | AT34: 0.527 | AU34: 0.026 | AV34: 0 | AW34: 0.048 | AX34: 0.49 | AY34: 112 | AZ34: 103 | BA34: 33.5 | BB34: 14.1
B35: 31 | C35: 706 | D35: 34 | E35: 45661 | F35: DEN | G35: @ | H35: SAS | I35: W, 122-111 (OT) | J35: =(_xlfn.TEXTBEFORE(_xlfn.TEXTAFTER($I35,", ",,1),"-",,1,1,))*1 -> 122 | K35: =(_xlfn.TEXTBEFORE(_xlfn.TEXTAFTER($I35,"-",,1)," ",,1,1,))*1 -> 111 | L35: =LEFT(' #StatsTable'!$I35,1) -> W | M35: =IF(' #StatsTable'!$L35="W", M34+1,M34) -> 20 | N35: =IF(' #StatsTable'!$L35="L",N34+1,N34) -> 14 | O35: * | P35: 1.8048611 | Q35: 19 | R35: 35 | S35: 0.543 | T35: 3 | U35: 8 | V35: 0.375 | W35: 16 | X35: 27 | Y35: 0.593 | Z35: 0.586 | AA35: 5 | AB35: 6 | AC35: 0.833 | AD35: 4 | AE35: 5 | AF35: 9 | AG35: 10 | AH35: 2 | AI35: 2 | AJ35: 2 | AK35: 3 | AL35: 46 | AM35: 40.2 | AN35: 7 | AO35: 0.611 | AP35: 0.586 | AQ35: 0.083 | AR35: 0.107 | AS35: 0.095 | AT35: 0.515 | AU35: 0.022 | AV35: 0.044 | AW35: 0.05 | AX35: 0.388 | AY35: 127 | AZ35: 102 | BA35: 40.2 | BB35: 20.1
B36: 31 | D36: 35 | E36: 45664 | F36: DEN | H36: BOS | I36: L, 106-118 | J36: =(_xlfn.TEXTBEFORE(_xlfn.TEXTAFTER($I36,", ",,1),"-",,1,1,))*1 -> 106 | K36: =(_xlfn.TEXTBEFORE(_xlfn.TEXTAFTER($I36,"-",,1)," ",,1,1,))*1 -> 118 | L36: =LEFT(' #StatsTable'!$I36,1) -> L | M36: =IF(' #StatsTable'!$L36="W", M35+1,M35) -> 20 | N36: =IF(' #StatsTable'!$L36="L",N35+1,N35) -> 15 | O36: Inactive | P36: - | Q36: - | R36: - | S36: - | T36: - | U36: - | V36: - | W36: - | X36: - | Y36: - | Z36: - | AA36: - | AB36: - | AC36: - | AD36: - | AE36: - | AF36: - | AG36: - | AH36: - | AI36: - | AJ36: - | AK36: - | AL36: - | AM36: - | AN36: - | AO36: - | AP36: - | AQ36: - | AR36: - | AS36: - | AT36: - | AU36: - | AV36: - | AW36: - | AX36: - | AY36: - | AZ36: - | BA36: - | BB36: -
B37: 31 | D37: 36 | E37: 45665 | F37: DEN | H37: LAC | I37: W, 126-103 | J37: =(_xlfn.TEXTBEFORE(_xlfn.TEXTAFTER($I37,", ",,1),"-",,1,1,))*1 -> 126 | K37: =(_xlfn.TEXTBEFORE(_xlfn.TEXTAFTER($I37,"-",,1)," ",,1,1,))*1 -> 103 | L37: =LEFT(' #StatsTable'!$I37,1) -> W | M37: =IF(' #StatsTable'!$L37="W", M36+1,M36) -> 21 | N37: =IF(' #StatsTable'!$L37="L",N36+1,N36) -> 15 | O37: Inactive | P37: - | Q37: - | R37: - | S37: - | T37: - | U37: - | V37: - | W37: - | X37: - | Y37: - | Z37: - | AA37: - | AB37: - | AC37: - | AD37: - | AE37: - | AF37: - | AG37: - | AH37: - | AI37: - | AJ37: - | AK37: - | AL37: - | AM37: - | AN37: - | AO37: - | AP37: - | AQ37: - | AR37: - | AS37: - | AT37: - | AU37: - | AV37: - | AW37: - | AX37: - | AY37: - | AZ37: - | BA37: - | BB37: -
B38: 32 | C38: 707 | D38: 37 | E38: 45667 | F38: DEN | H38: BRK | I38: W, 124-105 | J38: =(_xlfn.TEXTBEFORE(_xlfn.TEXTAFTER($I38,", ",,1),"-",,1,1,))*1 -> 124 | K38: =(_xlfn.TEXTBEFORE(_xlfn.TEXTAFTER($I38,"-",,1)," ",,1,1,))*1 -> 105 | L38: =LEFT(' #StatsTable'!$I38,1) -> W | M38: =IF(' #StatsTable'!$L38="W", M37+1,M37) -> 22 | N38: =IF(' #StatsTable'!$L38="L",N37+1,N37) -> 15 | O38: * | P38: 1.5909722 | Q38: 14 | R38: 21 | S38: 0.667 | T38: 1 | U38: 1 | V38: 1 | W38: 13 | X38: 20 | Y38: 0.65 | Z38: 0.69 | AA38: 6 | AB38: 8 | AC38: 0.75 | AD38: 5 | AE38: 7 | AF38: 12 | AG38: 15 | AH38: 4 | AI38: 0 | AJ38: 1 | AK38: 1 | AL38: 35 | AM38: 43.8 | AN38: 33 | AO38: 0.714 | AP38: 0.69 | AQ38: 0.153 | AR38: 0.187 | AS38: 0.171 | AT38: 0.688 | AU38: 0.049 | AV38: 0 | AW38: 0.039 | AX38: 0.275 | AY38: 160 | AZ38: 97 | BA38: 43.8 | BB38: 25.1
B39: 33 | C39: 708 | D39: 38 | E39: 45669 | F39: DEN | G39: @ | H39: DAL | I39: W, 112-101 | J39: =(_xlfn.TEXTBEFORE(_xlfn.TEXTAFTER($I39,", ",,1),"-",,1,1,))*1 -> 112 | K39: =(_xlfn.TEXTBEFORE(_xlfn.TEXTAFTER($I39,"-",,1)," ",,1,1,))*1 -> 101 | L39: =LEFT(' #StatsTable'!$I39,1) -> W | M39: =IF(' #StatsTable'!$L39="W", M38+1,M38) -> 23 | N39: =IF(' #StatsTable'!$L39="L",N38+1,N38) -> 15 | O39: * | P39: 1.6097222 | Q39: 6 | R39: 13 | S39: 0.462 | T39: 0 | U39: 2 | V39: 0 | W39: 6 | X39: 11 | Y39: 0.545 | Z39: 0.462 | AA39: 7 | AB39: 9 | AC39: 0.778 | AD39: 4 | AE39: 14 | AF39: 18 | AG39: 9 | AH39: 3 | AI39: 0 | AJ39: 4 | AK39: 4 | AL39: 19 | AM39: 22.2 | AN39: -2 | AO39: 0.56 | AP39: 0.462 | AQ39: 0.113 | AR39: 0.362 | AS39: 0.243 | AT39: 0.29 | AU39: 0.038 | AV39: 0 | AW39: 0.191 | AX39: 0.223 | AY39: 118 | AZ39: 94 | BA39: 22.2 | BB39: 8.6
B40: 34 | C40: 709 | D40: 39 | E40: 45671 | F40: DEN | G40: @ | H40: DAL | I40: W, 118-99 | J40: =(_xlfn.TEXTBEFORE(_xlfn.TEXTAFTER($I40,", ",,1),"-",,1,1,))*1 -> 118 | K40: =(_xlfn.TEXTBEFORE(_xlfn.TEXTAFTER($I40,"-",,1)," ",,1,1,))*1 -> 99 | L40: =LEFT(' #StatsTable'!$I40,1) -> W | M40: =IF(' #StatsTable'!$L40="W", M39+1,M39) -> 24 | N40: =IF(' #StatsTable'!$L40="L",N39+1,N39) -> 15 | O40: * | P40: 1.2055556 | Q40: 4 | R40: 7 | S40: 0.571 | T40: 1 | U40: 2 | V40: 0.5 | W40: 3 | X40: 5 | Y40: 0.6 | Z40: 0.643 | AA40: 1 | AB40: 2 | AC40: 0.5 | AD40: 2 | AE40: 12 | AF40: 14 | AG40: 10 | AH40: 2 | AI40: 0 | AJ40: 1 | AK40: 3 | AL40: 10 | AM40: 18.1 | AN40: 23 | AO40: 0.635 | AP40: 0.643 | AQ40: 0.101 | AR40: 0.415 | AS40: 0.287 | AT40: 0.456 | AU40: 0.033 | AV40: 0 | AW40: 0.113 | AX40: 0.131 | AY40: 155 | AZ40: 92 | BA40: 18.1 | BB40: 13.2
...

Sheet #PlusMinus v. DRtg
B1: Gseason | C1: Gplayed | D1: DRtg | E1: +/-
B2: 1 | C2: 1 | D2: 99 | E2: -9 | G2: SUMMARY OUTPUT | R2: SUMMARY OUTPUT
B3: 2 | C3: 2 | D3: 114 | E3: 7
B4: 3 | C4: 3 | D4: 112 | E4: 9 | G4: Regression Statistics | R4: Regression Statistics
B5: 4 | C5: 4 | D5: 129 | E5: 8 | G5: Multiple R | H5: 0.6011696 | R5: Multiple R | S5: 0.6011696
B6: 5 | C6: 5 | D6: 115 | E6: 6 | G6: R Square | H6: 0.36140489 | R6: R Square | S6: 0.36140489
B7: 6 | C7: 6 | D7: 95 | E7: 31 | G7: Adjusted R Square | H7: 0.35201379 | R7: Adjusted R Square | S7: 0.35201379
B8: 7 | C8: 7 | D8: 113 | E8: -1 | G8: Standard Error | H8: 11.470978 | R8: Standard Error | S8: 10.386668
B9: 8 | C9: 8 | D9: 105 | E9: 8 | G9: Observations | H9: 70 | R9: Observations | S9: 70
B10: 9 | C10: 9 | D10: 117 | E10: 26
B11: 10 | C11: 10 | D11: 117 | E11: 13 | G11: ANOVA | R11: ANOVA
B12: 14 | C12: 11 | D12: 121 | E12: 4 | H12: df | I12: SS | J12: MS | K12: F | L12: Significance F | S12: df | T12: SS | U12: MS | V12: F | W12: Significance F
B13: 15 | C13: 12 | D13: 95 | E13: 39 | G13: Regression | H13: 1 | I13: 5063.8195 | J13: 5063.8195 | K13: 38.483747 | L13: 3.735945e-08 | R13: Regression | S13: 1 | T13: 4151.7368 | U13: 4151.7368 | V13: 38.483747 | W13: 3.735945e-08
B14: 16 | C14: 13 | D14: 144 | E14: -20 | G14: Residual | H14: 68 | I14: 8947.6662 | J14: 131.58333 | R14: Residual | S14: 68 | T14: 7336.0346 | U14: 107.88286
B15: 17 | C15: 14 | D15: 107 | E15: 20 | G15: Total | H15: 69 | I15: 14011.486 | R15: Total | S15: 69 | T15: 11487.771
B16: 18 | C16: 15 | D16: 120 | E16: -7
B17: 19 | C17: 16 | D17: 100 | E17: 23 | H17: Coefficients | I17: Standard Error | J17: t Stat | K17: P-value | L17: Lower 95% | M17: Upper 95% | N17: Lower 95.0% | O17: Upper 95.0% | S17: Coefficients | T17: Standard Error | U17: t Stat | V17: P-value | W17: Lower 95% | X17: Upper 95% | Y17: Lower 95.0% | Z17: Upper 95.0%
B18: 20 | C18: 17 | D18: 108 | E18: -8 | G18: Intercept | H18: 82.143822 | I18: 11.952481 | J18: 6.8725334 | K18: 2.4048422e-09 | L18: 58.293019 | M18: 105.99463 | N18: 58.293019 | O18: 105.99463 | R18: Intercept | S18: 115.562 | T18: 1.4476228 | U18: 79.828807 | V18: 6.1382897e-69 | W18: 112.67331 | X18: 118.45068 | Y18: 112.67331 | Z18: 118.45068
B19: 21 | C19: 18 | D19: 118 | E19: -1 | G19: DRtg | H19: -0.66392835 | I19: 0.10702434 | J19: -6.203527 | K19: 3.735945e-08 | L19: -0.87749209 | M19: -0.45036462 | N19: -0.87749209 | O19: -0.45036462 | R19: +/- | S19: -0.54434321 | T19: 0.087747376 | U19: -6.203527 | V19: 3.735945e-08 | W19: -0.71944037 | X19: -0.36924605 | Y19: -0.71944037 | Z19: -0.36924605
B20: 22 | C20: 19 | D20: 94 | E20: 25
B21: 23 | C21: 20 | D21: 93 | E21: 14
B22: 24 | C22: 21 | D22: 113 | E22: 4
B23: 25 | C23: 22 | D23: 128 | E23: -5
B24: 26 | C24: 23 | D24: 108 | E24: 6
B25: 27 | C25: 24 | D25: 104 | E25: 19
B26: 28 | C26: 25 | D26: 112 | E26: -3
B27: 29 | C27: 26 | D27: 134 | E27: -15
B28: 30 | C28: 27 | D28: 123 | E28: 25
B29: 31 | C29: 28 | D29: 110 | E29: 20
B30: 32 | C30: 29 | D30: 104 | E30: 31
B31: 33 | C31: 30 | D31: 103 | E31: 7
... B71: 82 | C71: 70 | D71: 108 | E71: 34

Sheet #AdvStatsExplained
A1: TS% -- True Shooting Percentage
A2: A measure of shooting efficiency that takes into account 2-point field goals, 3-point field goals, and free throws.
A3: eFG% -- Effective Field Goal Percentage
A4: This statistic adjusts for the fact that a 3-point field goal is worth one more point than a 2-point field goal.
A5: ORB% -- Offensive Rebound Percentage
A6: An estimate of the percentage of available offensive rebounds a player grabbed while they were on the floor.
A7: DRB% -- Defensive Rebound Percentage
A8: An estimate of the percentage of available defensive rebounds a player grabbed while they were on the floor.
A9: TRB% -- Total Rebound Percentage
A10: An estimate of the percentage of available rebounds a player grabbed while they were on the floor.
A11: AST% -- Assist Percentage
A12: An estimate of the percentage of teammate field goals a player assisted while they were on the floor.
... A27: A box score estimate of the points per 100 possessions a player contributed above a league-average player, translated to an average team.

Sheet PivotTable
A3: Sum of PTS | B3: Column Labels | E3: L | F3: W
A4: Row Labels | B4: L | C4: W | E4: 16
A5: 1 | B5: 16 | E5: 41
A6: 2 | B6: 41 | F6: 40
A7: 3 | C7: 40 | F7: 29
A8: 4 | C8: 29 | E8: 26
A9: 5 | B9: 26 | F9: 27
A10: 6 | C10: 27 | F10: 28
A11: 7 | C11: 28 | F11: 23
A12: 8 | C12: 23 | F12: 30
A13: 9 | C13: 30 | F13: 37
A14: 10 | B14: 0 | C14: 37 | E14: 33
A15: 11 | B15: 33 | F15: 34
A16: 12 | C16: 34 | E16: 22
A17: 13 | B17: 22 | F17: 30
A18: 14 | C18: 30 | E18: 28
A19: 15 | B19: 28 | F19: 38
A20: 16 | C20: 38 | E20: 27
A21: 17 | B21: 27 | E21: 56
A22: 18 | B22: 56 | F22: 48
A23: 19 | C23: 48 | F23: 16
A24: 20 | C24: 16 | F24: 20
A25: 21 | C25: 20 | E25: 34
A26: 22 | B26: 34 | F26: 27
A27: 23 | C27: 27 | F27: 32
A28: 24 | C28: 32 | E28: 25
A29: 25 | B29: 25 | E29: 27
A30: 26 | B30: 27 | F30: 37
A31: 27 | C31: 37 | F31: 36
A32: 28 | C32: 36 | F32: 23
A33: 29 | C33: 23 | E33: 41
A34: 30 | B34: 41 | F34: 46
A35: 31 | B35: 0 | C35: 46 | F35: 35
A36: 32 | C36: 35 | F36: 19
A37: 33 | C37: 19 | F37: 10
A38: 34 | B38: 0 | C38: 10 | F38: 24
A39: 35 | C39: 24 | F39: 20
A40: 36 | C40: 20 | F40: 27
A41: 37 | C41: 27 | F41: 35
A42: 38 | C42: 35 | E42: 20
...

Sheet DefVisual
B2: Values | C2: W | D2: L
B3: Average of DRB | C3: 10.23913 | D3: 9.2083333
B4: Average of BLK | C4: 0.7173913 | D4: 0.5
B5: Average of STL | C5: 1.9565217 | D5: 1.5416667
B6: Average of PF | C6: 2.2608696 | D6: 2.3333333
B11: Values | C11: W | D11: L
B12: Average of DRB% | C12: 0.29134783 | D12: 0.26620833
B13: Average of BLK% | C13: 0.016543478 | D13: 0.011958333
B14: Average of STL% | C14: 0.026021739 | D14: 0.019666667
